<?xml version="1.0" encoding="UTF-8"?>
<!-- Generated by org.testng.reporters.JUnitReportReporter -->
<testsuite hostname="DESKTOP-AUMA2HC" failures="1" tests="5" name="Com.TestNG.Test.DemoTest2" time="0.005" errors="0" timestamp="2023-03-16T12:17:44 IST" skipped="0">
  <testcase classname="Com.TestNG.Test.DemoTest2" name="LoginTitle" time="0.001">
    <failure message="expected [true] but found [false]" type="java.lang.AssertionError">
      <![CDATA[java.lang.AssertionError: expected [true] but found [false]
at org.testng.Assert.fail(Assert.java:99)
at org.testng.Assert.failNotEquals(Assert.java:1037)
at org.testng.Assert.assertTrue(Assert.java:45)
at org.testng.Assert.assertTrue(Assert.java:55)
at Com.TestNG.Test.DemoTest2.LoginTitle(DemoTest2.java:28)
at java.base/jdk.internal.reflect.NativeMethodAccessorImpl.invoke0(Native Method)
at java.base/jdk.internal.reflect.NativeMethodAccessorImpl.invoke(NativeMethodAccessorImpl.java:62)
at java.base/jdk.internal.reflect.DelegatingMethodAccessorImpl.invoke(DelegatingMethodAccessorImpl.java:43)
at java.base/java.lang.reflect.Method.invoke(Method.java:566)
at org.testng.internal.MethodInvocationHelper.invokeMethod(MethodInvocationHelper.java:133)
at org.testng.internal.TestInvoker.invokeMethod(TestInvoker.java:598)
at org.testng.internal.TestInvoker.invokeTestMethod(TestInvoker.java:173)
at org.testng.internal.MethodRunner.runInSequence(MethodRunner.java:46)
at org.testng.internal.TestInvoker$MethodInvocationAgent.invoke(TestInvoker.java:824)
at org.testng.internal.TestInvoker.invokeTestMethods(TestInvoker.java:146)
at org.testng.internal.TestMethodWorker.invokeTestMethods(TestMethodWorker.java:146)
at org.testng.internal.TestMethodWorker.run(TestMethodWorker.java:128)
at java.base/java.util.ArrayList.forEach(ArrayList.java:1541)
at org.testng.TestRunner.privateRun(TestRunner.java:794)
at org.testng.TestRunner.run(TestRunner.java:596)
at org.testng.SuiteRunner.runTest(SuiteRunner.java:377)
at org.testng.SuiteRunner.access$000(SuiteRunner.java:28)
at org.testng.SuiteRunner$SuiteWorker.run(SuiteRunner.java:418)
at org.testng.internal.thread.ThreadUtil.lambda$execute$0(ThreadUtil.java:64)
at java.base/java.util.concurrent.FutureTask.run(FutureTask.java:264)
at java.base/java.util.concurrent.ThreadPoolExecutor.runWorker(ThreadPoolExecutor.java:1128)
at java.base/java.util.concurrent.ThreadPoolExecutor$Worker.run(ThreadPoolExecutor.java:628)
at java.base/java.lang.Thread.run(Thread.java:834)
]]>
    </failure>
  </testcase> <!-- LoginTitle -->
  <system-out/>
  <testcase classname="Com.TestNG.Test.DemoTest2" name="DashboardTitle" time="0.000"/>
  <system-out/>
  <testcase classname="Com.TestNG.Test.DemoTest2" name="Dashboard" time="0.002"/>
  <system-out/>
  <testcase classname="Com.TestNG.Test.DemoTest2" name="Login" time="0.001"/>
  <system-out/>
  <testcase classname="Com.TestNG.Test.DemoTest2" name="User" time="0.001"/>
  <system-out/>
</testsuite> <!-- Com.TestNG.Test.DemoTest2 -->
